[2024-08-05T08:57:59.801+0300] {local_task_job_runner.py:120} INFO - ::group::Pre task execution logs
[2024-08-05T08:57:59.830+0300] {taskinstance.py:2076} INFO - Dependencies all met for dep_context=non-requeueable deps ti=<TaskInstance: air_pollution_data_dag.fetch_air_pollution_data_Los_Angeles manual__2024-08-05T05:57:13.211101+00:00 [queued]>
[2024-08-05T08:57:59.836+0300] {taskinstance.py:2076} INFO - Dependencies all met for dep_context=requeueable deps ti=<TaskInstance: air_pollution_data_dag.fetch_air_pollution_data_Los_Angeles manual__2024-08-05T05:57:13.211101+00:00 [queued]>
[2024-08-05T08:57:59.837+0300] {taskinstance.py:2306} INFO - Starting attempt 1 of 2
[2024-08-05T08:57:59.860+0300] {taskinstance.py:2330} INFO - Executing <Task(PythonOperator): fetch_air_pollution_data_Los_Angeles> on 2024-08-05 05:57:13.211101+00:00
[2024-08-05T08:57:59.866+0300] {standard_task_runner.py:64} INFO - Started process 11757 to run task
[2024-08-05T08:57:59.869+0300] {standard_task_runner.py:90} INFO - Running: ['airflow', 'tasks', 'run', 'air_pollution_data_dag', 'fetch_air_pollution_data_Los_Angeles', 'manual__2024-08-05T05:57:13.211101+00:00', '--job-id', '8', '--raw', '--subdir', 'DAGS_FOLDER/air_pollution_data_dag.py', '--cfg-path', '/tmp/tmpw264b3ju']
[2024-08-05T08:57:59.870+0300] {standard_task_runner.py:91} INFO - Job 8: Subtask fetch_air_pollution_data_Los_Angeles
[2024-08-05T08:57:59.921+0300] {task_command.py:426} INFO - Running <TaskInstance: air_pollution_data_dag.fetch_air_pollution_data_Los_Angeles manual__2024-08-05T05:57:13.211101+00:00 [running]> on host std21092
[2024-08-05T08:58:00.002+0300] {taskinstance.py:2648} INFO - Exporting env vars: AIRFLOW_CTX_DAG_OWNER='airflow' AIRFLOW_CTX_DAG_ID='air_pollution_data_dag' AIRFLOW_CTX_TASK_ID='fetch_air_pollution_data_Los_Angeles' AIRFLOW_CTX_EXECUTION_DATE='2024-08-05T05:57:13.211101+00:00' AIRFLOW_CTX_TRY_NUMBER='1' AIRFLOW_CTX_DAG_RUN_ID='manual__2024-08-05T05:57:13.211101+00:00'
[2024-08-05T08:58:00.002+0300] {taskinstance.py:430} INFO - ::endgroup::
[2024-08-05T09:00:38.841+0300] {taskinstance.py:441} INFO - ::group::Post task execution logs
[2024-08-05T09:00:38.841+0300] {taskinstance.py:2905} ERROR - Task failed with exception
Traceback (most recent call last):
  File "/home/safidy/.local/lib/python3.9/site-packages/urllib3/connectionpool.py", line 714, in urlopen
    httplib_response = self._make_request(
  File "/home/safidy/.local/lib/python3.9/site-packages/urllib3/connectionpool.py", line 466, in _make_request
    six.raise_from(e, None)
  File "<string>", line 3, in raise_from
  File "/home/safidy/.local/lib/python3.9/site-packages/urllib3/connectionpool.py", line 461, in _make_request
    httplib_response = conn.getresponse()
  File "/usr/lib/python3.9/http/client.py", line 1347, in getresponse
    response.begin()
  File "/usr/lib/python3.9/http/client.py", line 307, in begin
    version, status, reason = self._read_status()
  File "/usr/lib/python3.9/http/client.py", line 268, in _read_status
    line = str(self.fp.readline(_MAXLINE + 1), "iso-8859-1")
  File "/usr/lib/python3.9/socket.py", line 704, in readinto
    return self._sock.recv_into(b)
ConnectionResetError: [Errno 104] Connection reset by peer

During handling of the above exception, another exception occurred:

Traceback (most recent call last):
  File "/home/safidy/.local/lib/python3.9/site-packages/requests/adapters.py", line 486, in send
    resp = conn.urlopen(
  File "/home/safidy/.local/lib/python3.9/site-packages/urllib3/connectionpool.py", line 798, in urlopen
    retries = retries.increment(
  File "/home/safidy/.local/lib/python3.9/site-packages/urllib3/util/retry.py", line 550, in increment
    raise six.reraise(type(error), error, _stacktrace)
  File "/home/safidy/.local/lib/python3.9/site-packages/urllib3/packages/six.py", line 769, in reraise
    raise value.with_traceback(tb)
  File "/home/safidy/.local/lib/python3.9/site-packages/urllib3/connectionpool.py", line 714, in urlopen
    httplib_response = self._make_request(
  File "/home/safidy/.local/lib/python3.9/site-packages/urllib3/connectionpool.py", line 466, in _make_request
    six.raise_from(e, None)
  File "<string>", line 3, in raise_from
  File "/home/safidy/.local/lib/python3.9/site-packages/urllib3/connectionpool.py", line 461, in _make_request
    httplib_response = conn.getresponse()
  File "/usr/lib/python3.9/http/client.py", line 1347, in getresponse
    response.begin()
  File "/usr/lib/python3.9/http/client.py", line 307, in begin
    version, status, reason = self._read_status()
  File "/usr/lib/python3.9/http/client.py", line 268, in _read_status
    line = str(self.fp.readline(_MAXLINE + 1), "iso-8859-1")
  File "/usr/lib/python3.9/socket.py", line 704, in readinto
    return self._sock.recv_into(b)
urllib3.exceptions.ProtocolError: ('Connection aborted.', ConnectionResetError(104, 'Connection reset by peer'))

During handling of the above exception, another exception occurred:

Traceback (most recent call last):
  File "/home/safidy/.local/lib/python3.9/site-packages/airflow/models/taskinstance.py", line 465, in _execute_task
    result = _execute_callable(context=context, **execute_callable_kwargs)
  File "/home/safidy/.local/lib/python3.9/site-packages/airflow/models/taskinstance.py", line 432, in _execute_callable
    return execute_callable(context=context, **execute_callable_kwargs)
  File "/home/safidy/.local/lib/python3.9/site-packages/airflow/models/baseoperator.py", line 401, in wrapper
    return func(self, *args, **kwargs)
  File "/home/safidy/.local/lib/python3.9/site-packages/airflow/operators/python.py", line 235, in execute
    return_value = self.execute_callable()
  File "/home/safidy/.local/lib/python3.9/site-packages/airflow/operators/python.py", line 252, in execute_callable
    return self.python_callable(*self.op_args, **self.op_kwargs)
  File "/home/safidy/airflow/dags/air_pollution_data_dag.py", line 26, in fetch_air_pollution_data
    response = requests.get(url)
  File "/home/safidy/.local/lib/python3.9/site-packages/requests/api.py", line 73, in get
    return request("get", url, params=params, **kwargs)
  File "/home/safidy/.local/lib/python3.9/site-packages/requests/api.py", line 59, in request
    return session.request(method=method, url=url, **kwargs)
  File "/home/safidy/.local/lib/python3.9/site-packages/requests/sessions.py", line 589, in request
    resp = self.send(prep, **send_kwargs)
  File "/home/safidy/.local/lib/python3.9/site-packages/requests/sessions.py", line 703, in send
    r = adapter.send(request, **kwargs)
  File "/home/safidy/.local/lib/python3.9/site-packages/requests/adapters.py", line 501, in send
    raise ConnectionError(err, request=request)
requests.exceptions.ConnectionError: ('Connection aborted.', ConnectionResetError(104, 'Connection reset by peer'))
[2024-08-05T09:00:38.856+0300] {taskinstance.py:1206} INFO - Marking task as UP_FOR_RETRY. dag_id=air_pollution_data_dag, task_id=fetch_air_pollution_data_Los_Angeles, run_id=manual__2024-08-05T05:57:13.211101+00:00, execution_date=20240805T055713, start_date=20240805T055759, end_date=20240805T060038
[2024-08-05T09:00:38.870+0300] {standard_task_runner.py:110} ERROR - Failed to execute job 8 for task fetch_air_pollution_data_Los_Angeles (('Connection aborted.', ConnectionResetError(104, 'Connection reset by peer')); 11757)
[2024-08-05T09:00:38.888+0300] {local_task_job_runner.py:243} INFO - Task exited with return code 1
[2024-08-05T09:00:38.909+0300] {taskinstance.py:3503} INFO - 0 downstream tasks scheduled from follow-on schedule check
[2024-08-05T09:00:38.910+0300] {local_task_job_runner.py:222} INFO - ::endgroup::
