[2024-08-05T14:22:49.625+0300] {local_task_job_runner.py:120} INFO - ::group::Pre task execution logs
[2024-08-05T14:22:49.664+0300] {taskinstance.py:2076} INFO - Dependencies all met for dep_context=non-requeueable deps ti=<TaskInstance: process_air_pollution_data_dag.clean_data scheduled__2024-08-04T00:00:00+00:00 [queued]>
[2024-08-05T14:22:49.671+0300] {taskinstance.py:2076} INFO - Dependencies all met for dep_context=requeueable deps ti=<TaskInstance: process_air_pollution_data_dag.clean_data scheduled__2024-08-04T00:00:00+00:00 [queued]>
[2024-08-05T14:22:49.672+0300] {taskinstance.py:2306} INFO - Starting attempt 2 of 2
[2024-08-05T14:22:49.687+0300] {taskinstance.py:2330} INFO - Executing <Task(PythonOperator): clean_data> on 2024-08-04 00:00:00+00:00
[2024-08-05T14:22:49.691+0300] {standard_task_runner.py:64} INFO - Started process 86806 to run task
[2024-08-05T14:22:49.696+0300] {standard_task_runner.py:90} INFO - Running: ['airflow', 'tasks', 'run', 'process_air_pollution_data_dag', 'clean_data', 'scheduled__2024-08-04T00:00:00+00:00', '--job-id', '309', '--raw', '--subdir', 'DAGS_FOLDER/process_air_pollution_data_dag.py', '--cfg-path', '/tmp/tmp33t1qnxa']
[2024-08-05T14:22:49.697+0300] {standard_task_runner.py:91} INFO - Job 309: Subtask clean_data
[2024-08-05T14:22:49.740+0300] {task_command.py:426} INFO - Running <TaskInstance: process_air_pollution_data_dag.clean_data scheduled__2024-08-04T00:00:00+00:00 [running]> on host std21092
[2024-08-05T14:22:49.821+0300] {taskinstance.py:2648} INFO - Exporting env vars: AIRFLOW_CTX_DAG_OWNER='airflow' AIRFLOW_CTX_DAG_ID='process_air_pollution_data_dag' AIRFLOW_CTX_TASK_ID='clean_data' AIRFLOW_CTX_EXECUTION_DATE='2024-08-04T00:00:00+00:00' AIRFLOW_CTX_TRY_NUMBER='2' AIRFLOW_CTX_DAG_RUN_ID='scheduled__2024-08-04T00:00:00+00:00'
[2024-08-05T14:22:49.822+0300] {taskinstance.py:430} INFO - ::endgroup::
[2024-08-05T14:22:49.824+0300] {taskinstance.py:441} INFO - ::group::Post task execution logs
[2024-08-05T14:22:49.824+0300] {taskinstance.py:2905} ERROR - Task failed with exception
Traceback (most recent call last):
  File "/home/safidy/.local/lib/python3.9/site-packages/airflow/models/taskinstance.py", line 465, in _execute_task
    result = _execute_callable(context=context, **execute_callable_kwargs)
  File "/home/safidy/.local/lib/python3.9/site-packages/airflow/models/taskinstance.py", line 432, in _execute_callable
    return execute_callable(context=context, **execute_callable_kwargs)
  File "/home/safidy/.local/lib/python3.9/site-packages/airflow/models/baseoperator.py", line 401, in wrapper
    return func(self, *args, **kwargs)
  File "/home/safidy/.local/lib/python3.9/site-packages/airflow/operators/python.py", line 235, in execute
    return_value = self.execute_callable()
  File "/home/safidy/.local/lib/python3.9/site-packages/airflow/operators/python.py", line 252, in execute_callable
    return self.python_callable(*self.op_args, **self.op_kwargs)
  File "/home/safidy/airflow/dags/process_air_pollution_data_dag.py", line 7, in clean_data
    df = pd.read_csv('/home/safidy/airflow/data/air_pollution_data.csv')
  File "/home/safidy/.local/lib/python3.9/site-packages/pandas/io/parsers/readers.py", line 912, in read_csv
    return _read(filepath_or_buffer, kwds)
  File "/home/safidy/.local/lib/python3.9/site-packages/pandas/io/parsers/readers.py", line 583, in _read
    return parser.read(nrows)
  File "/home/safidy/.local/lib/python3.9/site-packages/pandas/io/parsers/readers.py", line 1704, in read
    ) = self._engine.read(  # type: ignore[attr-defined]
  File "/home/safidy/.local/lib/python3.9/site-packages/pandas/io/parsers/c_parser_wrapper.py", line 234, in read
    chunks = self._reader.read_low_memory(nrows)
  File "pandas/_libs/parsers.pyx", line 814, in pandas._libs.parsers.TextReader.read_low_memory
  File "pandas/_libs/parsers.pyx", line 875, in pandas._libs.parsers.TextReader._read_rows
  File "pandas/_libs/parsers.pyx", line 850, in pandas._libs.parsers.TextReader._tokenize_rows
  File "pandas/_libs/parsers.pyx", line 861, in pandas._libs.parsers.TextReader._check_tokenize_status
  File "pandas/_libs/parsers.pyx", line 2029, in pandas._libs.parsers.raise_parser_error
pandas.errors.ParserError: Error tokenizing data. C error: Expected 3 fields in line 3, saw 10

[2024-08-05T14:22:49.830+0300] {taskinstance.py:1206} INFO - Marking task as FAILED. dag_id=process_air_pollution_data_dag, task_id=clean_data, run_id=scheduled__2024-08-04T00:00:00+00:00, execution_date=20240804T000000, start_date=20240805T112249, end_date=20240805T112249
[2024-08-05T14:22:49.888+0300] {standard_task_runner.py:110} ERROR - Failed to execute job 309 for task clean_data (Error tokenizing data. C error: Expected 3 fields in line 3, saw 10
; 86806)
[2024-08-05T14:22:49.907+0300] {local_task_job_runner.py:243} INFO - Task exited with return code 1
[2024-08-05T14:22:49.929+0300] {taskinstance.py:3503} INFO - 0 downstream tasks scheduled from follow-on schedule check
[2024-08-05T14:22:49.935+0300] {local_task_job_runner.py:222} INFO - ::endgroup::
[2024-08-05T14:39:24.651+0300] {local_task_job_runner.py:120} INFO - ::group::Pre task execution logs
[2024-08-05T14:39:24.676+0300] {taskinstance.py:2076} INFO - Dependencies all met for dep_context=non-requeueable deps ti=<TaskInstance: process_air_pollution_data_dag.clean_data scheduled__2024-08-04T00:00:00+00:00 [queued]>
[2024-08-05T14:39:24.684+0300] {taskinstance.py:2076} INFO - Dependencies all met for dep_context=requeueable deps ti=<TaskInstance: process_air_pollution_data_dag.clean_data scheduled__2024-08-04T00:00:00+00:00 [queued]>
[2024-08-05T14:39:24.684+0300] {taskinstance.py:2306} INFO - Starting attempt 2 of 2
[2024-08-05T14:39:24.698+0300] {taskinstance.py:2330} INFO - Executing <Task(PythonOperator): clean_data> on 2024-08-04 00:00:00+00:00
[2024-08-05T14:39:24.703+0300] {standard_task_runner.py:64} INFO - Started process 93065 to run task
[2024-08-05T14:39:24.706+0300] {standard_task_runner.py:90} INFO - Running: ['airflow', 'tasks', 'run', 'process_air_pollution_data_dag', 'clean_data', 'scheduled__2024-08-04T00:00:00+00:00', '--job-id', '309', '--raw', '--subdir', 'DAGS_FOLDER/process_air_pollution_data_dag.py', '--cfg-path', '/tmp/tmptnkrpft1']
[2024-08-05T14:39:24.707+0300] {standard_task_runner.py:91} INFO - Job 309: Subtask clean_data
[2024-08-05T14:39:24.748+0300] {task_command.py:426} INFO - Running <TaskInstance: process_air_pollution_data_dag.clean_data scheduled__2024-08-04T00:00:00+00:00 [running]> on host std21092
[2024-08-05T14:39:24.826+0300] {taskinstance.py:2648} INFO - Exporting env vars: AIRFLOW_CTX_DAG_OWNER='airflow' AIRFLOW_CTX_DAG_ID='process_air_pollution_data_dag' AIRFLOW_CTX_TASK_ID='clean_data' AIRFLOW_CTX_EXECUTION_DATE='2024-08-04T00:00:00+00:00' AIRFLOW_CTX_TRY_NUMBER='2' AIRFLOW_CTX_DAG_RUN_ID='scheduled__2024-08-04T00:00:00+00:00'
[2024-08-05T14:39:24.828+0300] {taskinstance.py:430} INFO - ::endgroup::
[2024-08-05T14:39:24.830+0300] {taskinstance.py:441} INFO - ::group::Post task execution logs
[2024-08-05T14:39:24.831+0300] {taskinstance.py:2905} ERROR - Task failed with exception
Traceback (most recent call last):
  File "/home/safidy/.local/lib/python3.9/site-packages/airflow/models/taskinstance.py", line 465, in _execute_task
    result = _execute_callable(context=context, **execute_callable_kwargs)
  File "/home/safidy/.local/lib/python3.9/site-packages/airflow/models/taskinstance.py", line 432, in _execute_callable
    return execute_callable(context=context, **execute_callable_kwargs)
  File "/home/safidy/.local/lib/python3.9/site-packages/airflow/models/baseoperator.py", line 401, in wrapper
    return func(self, *args, **kwargs)
  File "/home/safidy/.local/lib/python3.9/site-packages/airflow/operators/python.py", line 235, in execute
    return_value = self.execute_callable()
  File "/home/safidy/.local/lib/python3.9/site-packages/airflow/operators/python.py", line 252, in execute_callable
    return self.python_callable(*self.op_args, **self.op_kwargs)
  File "/home/safidy/airflow/dags/process_air_pollution_data_dag.py", line 8, in clean_data
    df = pd.read_csv('/home/safidy/airflow/data/air_pollution_data.csv')
  File "/home/safidy/.local/lib/python3.9/site-packages/pandas/io/parsers/readers.py", line 912, in read_csv
    return _read(filepath_or_buffer, kwds)
  File "/home/safidy/.local/lib/python3.9/site-packages/pandas/io/parsers/readers.py", line 583, in _read
    return parser.read(nrows)
  File "/home/safidy/.local/lib/python3.9/site-packages/pandas/io/parsers/readers.py", line 1704, in read
    ) = self._engine.read(  # type: ignore[attr-defined]
  File "/home/safidy/.local/lib/python3.9/site-packages/pandas/io/parsers/c_parser_wrapper.py", line 234, in read
    chunks = self._reader.read_low_memory(nrows)
  File "pandas/_libs/parsers.pyx", line 814, in pandas._libs.parsers.TextReader.read_low_memory
  File "pandas/_libs/parsers.pyx", line 875, in pandas._libs.parsers.TextReader._read_rows
  File "pandas/_libs/parsers.pyx", line 850, in pandas._libs.parsers.TextReader._tokenize_rows
  File "pandas/_libs/parsers.pyx", line 861, in pandas._libs.parsers.TextReader._check_tokenize_status
  File "pandas/_libs/parsers.pyx", line 2029, in pandas._libs.parsers.raise_parser_error
pandas.errors.ParserError: Error tokenizing data. C error: Expected 3 fields in line 3, saw 10

[2024-08-05T14:39:24.838+0300] {taskinstance.py:1206} INFO - Marking task as FAILED. dag_id=process_air_pollution_data_dag, task_id=clean_data, run_id=scheduled__2024-08-04T00:00:00+00:00, execution_date=20240804T000000, start_date=20240805T113924, end_date=20240805T113924
[2024-08-05T14:39:24.851+0300] {standard_task_runner.py:110} ERROR - Failed to execute job 309 for task clean_data (Error tokenizing data. C error: Expected 3 fields in line 3, saw 10
; 93065)
[2024-08-05T14:39:24.878+0300] {local_task_job_runner.py:243} INFO - Task exited with return code 1
[2024-08-05T14:39:24.902+0300] {taskinstance.py:3503} INFO - 0 downstream tasks scheduled from follow-on schedule check
[2024-08-05T14:39:24.910+0300] {local_task_job_runner.py:222} INFO - ::endgroup::
