[2024-08-05T10:58:42.088+0300] {local_task_job_runner.py:120} INFO - ::group::Pre task execution logs
[2024-08-05T10:58:42.121+0300] {taskinstance.py:2076} INFO - Dependencies all met for dep_context=non-requeueable deps ti=<TaskInstance: air_pollution_analysis.merge_data manual__2024-08-05T06:49:45.951409+00:00 [queued]>
[2024-08-05T10:58:42.129+0300] {taskinstance.py:2076} INFO - Dependencies all met for dep_context=requeueable deps ti=<TaskInstance: air_pollution_analysis.merge_data manual__2024-08-05T06:49:45.951409+00:00 [queued]>
[2024-08-05T10:58:42.130+0300] {taskinstance.py:2306} INFO - Starting attempt 8 of 8
[2024-08-05T10:58:42.145+0300] {taskinstance.py:2330} INFO - Executing <Task(PythonOperator): merge_data> on 2024-08-05 06:49:45.951409+00:00
[2024-08-05T10:58:42.151+0300] {standard_task_runner.py:64} INFO - Started process 42904 to run task
[2024-08-05T10:58:42.154+0300] {standard_task_runner.py:90} INFO - Running: ['airflow', 'tasks', 'run', 'air_pollution_analysis', 'merge_data', 'manual__2024-08-05T06:49:45.951409+00:00', '--job-id', '222', '--raw', '--subdir', 'DAGS_FOLDER/air_pollution_analysis_dag.py', '--cfg-path', '/tmp/tmpl44m43v4']
[2024-08-05T10:58:42.155+0300] {standard_task_runner.py:91} INFO - Job 222: Subtask merge_data
[2024-08-05T10:58:42.206+0300] {task_command.py:426} INFO - Running <TaskInstance: air_pollution_analysis.merge_data manual__2024-08-05T06:49:45.951409+00:00 [running]> on host std21092
[2024-08-05T10:58:42.335+0300] {taskinstance.py:2648} INFO - Exporting env vars: AIRFLOW_CTX_DAG_OWNER='airflow' AIRFLOW_CTX_DAG_ID='air_pollution_analysis' AIRFLOW_CTX_TASK_ID='merge_data' AIRFLOW_CTX_EXECUTION_DATE='2024-08-05T06:49:45.951409+00:00' AIRFLOW_CTX_TRY_NUMBER='8' AIRFLOW_CTX_DAG_RUN_ID='manual__2024-08-05T06:49:45.951409+00:00'
[2024-08-05T10:58:42.336+0300] {taskinstance.py:430} INFO - ::endgroup::
[2024-08-05T10:58:42.350+0300] {logging_mixin.py:188} INFO - Colonnes dans air_pollution_df: Index(['list', 'coord.lon', 'coord.lat'], dtype='object')
[2024-08-05T10:58:42.351+0300] {logging_mixin.py:188} INFO - Colonnes dans demographic_df: Index(['Location', 'Population', 'Density (people/km²)', 'Urbanization (%)',
       'Average Income (USD)',
       'Education Level (% with Bachelor's or higher)'],
      dtype='object')
[2024-08-05T10:58:42.351+0300] {logging_mixin.py:188} INFO - Colonnes dans geographic_df: Index(['Location', 'Altitude (m)', 'Proximity to Industry (km)'], dtype='object')
[2024-08-05T10:58:42.352+0300] {logging_mixin.py:188} INFO - Erreur lors de la fusion des données : 'city'
[2024-08-05T10:58:42.353+0300] {taskinstance.py:441} INFO - ::group::Post task execution logs
[2024-08-05T10:58:42.353+0300] {taskinstance.py:2905} ERROR - Task failed with exception
Traceback (most recent call last):
  File "/home/safidy/.local/lib/python3.9/site-packages/airflow/models/taskinstance.py", line 465, in _execute_task
    result = _execute_callable(context=context, **execute_callable_kwargs)
  File "/home/safidy/.local/lib/python3.9/site-packages/airflow/models/taskinstance.py", line 432, in _execute_callable
    return execute_callable(context=context, **execute_callable_kwargs)
  File "/home/safidy/.local/lib/python3.9/site-packages/airflow/models/baseoperator.py", line 401, in wrapper
    return func(self, *args, **kwargs)
  File "/home/safidy/.local/lib/python3.9/site-packages/airflow/operators/python.py", line 235, in execute
    return_value = self.execute_callable()
  File "/home/safidy/.local/lib/python3.9/site-packages/airflow/operators/python.py", line 252, in execute_callable
    return self.python_callable(*self.op_args, **self.op_kwargs)
  File "/home/safidy/airflow/dags/air_pollution_analysis_dag.py", line 65, in merge_data
    merged_df = pd.merge(air_pollution_df, demographic_df, left_on='city', right_on='Location')
  File "/home/safidy/.local/lib/python3.9/site-packages/pandas/core/reshape/merge.py", line 148, in merge
    op = _MergeOperation(
  File "/home/safidy/.local/lib/python3.9/site-packages/pandas/core/reshape/merge.py", line 737, in __init__
    ) = self._get_merge_keys()
  File "/home/safidy/.local/lib/python3.9/site-packages/pandas/core/reshape/merge.py", line 1221, in _get_merge_keys
    left_keys.append(left._get_label_or_level_values(lk))
  File "/home/safidy/.local/lib/python3.9/site-packages/pandas/core/generic.py", line 1778, in _get_label_or_level_values
    raise KeyError(key)
KeyError: 'city'
[2024-08-05T10:58:42.372+0300] {taskinstance.py:1206} INFO - Marking task as FAILED. dag_id=air_pollution_analysis, task_id=merge_data, run_id=manual__2024-08-05T06:49:45.951409+00:00, execution_date=20240805T064945, start_date=20240805T075842, end_date=20240805T075842
[2024-08-05T10:58:42.392+0300] {standard_task_runner.py:110} ERROR - Failed to execute job 222 for task merge_data ('city'; 42904)
[2024-08-05T10:58:42.410+0300] {local_task_job_runner.py:243} INFO - Task exited with return code 1
[2024-08-05T10:58:42.438+0300] {taskinstance.py:3503} INFO - 0 downstream tasks scheduled from follow-on schedule check
[2024-08-05T10:58:42.447+0300] {local_task_job_runner.py:222} INFO - ::endgroup::
