[2024-08-05T10:44:34.862+0300] {local_task_job_runner.py:120} INFO - ::group::Pre task execution logs
[2024-08-05T10:44:34.904+0300] {taskinstance.py:2076} INFO - Dependencies all met for dep_context=non-requeueable deps ti=<TaskInstance: air_pollution_analysis.merge_data manual__2024-08-05T06:49:45.951409+00:00 [queued]>
[2024-08-05T10:44:34.912+0300] {taskinstance.py:2076} INFO - Dependencies all met for dep_context=requeueable deps ti=<TaskInstance: air_pollution_analysis.merge_data manual__2024-08-05T06:49:45.951409+00:00 [queued]>
[2024-08-05T10:44:34.912+0300] {taskinstance.py:2306} INFO - Starting attempt 5 of 6
[2024-08-05T10:44:34.930+0300] {taskinstance.py:2330} INFO - Executing <Task(PythonOperator): merge_data> on 2024-08-05 06:49:45.951409+00:00
[2024-08-05T10:44:34.934+0300] {standard_task_runner.py:64} INFO - Started process 40131 to run task
[2024-08-05T10:44:34.940+0300] {standard_task_runner.py:90} INFO - Running: ['airflow', 'tasks', 'run', 'air_pollution_analysis', 'merge_data', 'manual__2024-08-05T06:49:45.951409+00:00', '--job-id', '217', '--raw', '--subdir', 'DAGS_FOLDER/air_pollution_analysis_dag.py', '--cfg-path', '/tmp/tmpvpychy63']
[2024-08-05T10:44:34.941+0300] {standard_task_runner.py:91} INFO - Job 217: Subtask merge_data
[2024-08-05T10:44:34.981+0300] {task_command.py:426} INFO - Running <TaskInstance: air_pollution_analysis.merge_data manual__2024-08-05T06:49:45.951409+00:00 [running]> on host std21092
[2024-08-05T10:44:35.051+0300] {taskinstance.py:2648} INFO - Exporting env vars: AIRFLOW_CTX_DAG_OWNER='airflow' AIRFLOW_CTX_DAG_ID='air_pollution_analysis' AIRFLOW_CTX_TASK_ID='merge_data' AIRFLOW_CTX_EXECUTION_DATE='2024-08-05T06:49:45.951409+00:00' AIRFLOW_CTX_TRY_NUMBER='5' AIRFLOW_CTX_DAG_RUN_ID='manual__2024-08-05T06:49:45.951409+00:00'
[2024-08-05T10:44:35.053+0300] {taskinstance.py:430} INFO - ::endgroup::
[2024-08-05T10:44:35.055+0300] {logging_mixin.py:188} INFO - Erreur lors de la fusion des donn√©es : [Errno 2] No such file or directory: '/path/to/your/data/cleaned_data.csv'
[2024-08-05T10:44:35.055+0300] {taskinstance.py:441} INFO - ::group::Post task execution logs
[2024-08-05T10:44:35.055+0300] {taskinstance.py:2905} ERROR - Task failed with exception
Traceback (most recent call last):
  File "/home/safidy/.local/lib/python3.9/site-packages/airflow/models/taskinstance.py", line 465, in _execute_task
    result = _execute_callable(context=context, **execute_callable_kwargs)
  File "/home/safidy/.local/lib/python3.9/site-packages/airflow/models/taskinstance.py", line 432, in _execute_callable
    return execute_callable(context=context, **execute_callable_kwargs)
  File "/home/safidy/.local/lib/python3.9/site-packages/airflow/models/baseoperator.py", line 401, in wrapper
    return func(self, *args, **kwargs)
  File "/home/safidy/.local/lib/python3.9/site-packages/airflow/operators/python.py", line 235, in execute
    return_value = self.execute_callable()
  File "/home/safidy/.local/lib/python3.9/site-packages/airflow/operators/python.py", line 252, in execute_callable
    return self.python_callable(*self.op_args, **self.op_kwargs)
  File "/home/safidy/airflow/dags/air_pollution_analysis_dag.py", line 65, in merge_data
    merged_df = pd.merge(air_pollution_df, demographic_df, left_on='city', right_on='Location')
UnboundLocalError: local variable 'air_pollution_df' referenced before assignment
[2024-08-05T10:44:35.063+0300] {taskinstance.py:1206} INFO - Marking task as UP_FOR_RETRY. dag_id=air_pollution_analysis, task_id=merge_data, run_id=manual__2024-08-05T06:49:45.951409+00:00, execution_date=20240805T064945, start_date=20240805T074434, end_date=20240805T074435
[2024-08-05T10:44:35.076+0300] {standard_task_runner.py:110} ERROR - Failed to execute job 217 for task merge_data (local variable 'air_pollution_df' referenced before assignment; 40131)
[2024-08-05T10:44:35.110+0300] {local_task_job_runner.py:243} INFO - Task exited with return code 1
[2024-08-05T10:44:35.131+0300] {taskinstance.py:3503} INFO - 0 downstream tasks scheduled from follow-on schedule check
[2024-08-05T10:44:35.131+0300] {local_task_job_runner.py:222} INFO - ::endgroup::
