[2024-08-05T11:38:15.358+0300] {local_task_job_runner.py:120} INFO - ::group::Pre task execution logs
[2024-08-05T11:38:15.398+0300] {taskinstance.py:2076} INFO - Dependencies all met for dep_context=non-requeueable deps ti=<TaskInstance: air_pollution_analysis.fetch_air_pollution_data manual__2024-08-05T08:38:08.208342+00:00 [queued]>
[2024-08-05T11:38:15.406+0300] {taskinstance.py:2076} INFO - Dependencies all met for dep_context=requeueable deps ti=<TaskInstance: air_pollution_analysis.fetch_air_pollution_data manual__2024-08-05T08:38:08.208342+00:00 [queued]>
[2024-08-05T11:38:15.406+0300] {taskinstance.py:2306} INFO - Starting attempt 1 of 2
[2024-08-05T11:38:15.432+0300] {taskinstance.py:2330} INFO - Executing <Task(PythonOperator): fetch_air_pollution_data> on 2024-08-05 08:38:08.208342+00:00
[2024-08-05T11:38:15.441+0300] {standard_task_runner.py:90} INFO - Running: ['airflow', 'tasks', 'run', 'air_pollution_analysis', 'fetch_air_pollution_data', 'manual__2024-08-05T08:38:08.208342+00:00', '--job-id', '236', '--raw', '--subdir', 'DAGS_FOLDER/air_pollution_data_dag.py', '--cfg-path', '/tmp/tmpv4koatua']
[2024-08-05T11:38:15.442+0300] {standard_task_runner.py:91} INFO - Job 236: Subtask fetch_air_pollution_data
[2024-08-05T11:38:15.437+0300] {standard_task_runner.py:64} INFO - Started process 48583 to run task
[2024-08-05T11:38:15.512+0300] {task_command.py:426} INFO - Running <TaskInstance: air_pollution_analysis.fetch_air_pollution_data manual__2024-08-05T08:38:08.208342+00:00 [running]> on host std21092
[2024-08-05T11:38:15.588+0300] {taskinstance.py:2648} INFO - Exporting env vars: AIRFLOW_CTX_DAG_OWNER='airflow' AIRFLOW_CTX_DAG_ID='air_pollution_analysis' AIRFLOW_CTX_TASK_ID='fetch_air_pollution_data' AIRFLOW_CTX_EXECUTION_DATE='2024-08-05T08:38:08.208342+00:00' AIRFLOW_CTX_TRY_NUMBER='1' AIRFLOW_CTX_DAG_RUN_ID='manual__2024-08-05T08:38:08.208342+00:00'
[2024-08-05T11:38:15.589+0300] {taskinstance.py:430} INFO - ::endgroup::
[2024-08-05T11:38:15.590+0300] {taskinstance.py:441} INFO - ::group::Post task execution logs
[2024-08-05T11:38:15.591+0300] {taskinstance.py:2905} ERROR - Task failed with exception
Traceback (most recent call last):
  File "/home/safidy/.local/lib/python3.9/site-packages/airflow/models/taskinstance.py", line 465, in _execute_task
    result = _execute_callable(context=context, **execute_callable_kwargs)
  File "/home/safidy/.local/lib/python3.9/site-packages/airflow/models/taskinstance.py", line 432, in _execute_callable
    return execute_callable(context=context, **execute_callable_kwargs)
  File "/home/safidy/.local/lib/python3.9/site-packages/airflow/models/baseoperator.py", line 401, in wrapper
    return func(self, *args, **kwargs)
  File "/home/safidy/.local/lib/python3.9/site-packages/airflow/operators/python.py", line 235, in execute
    return_value = self.execute_callable()
  File "/home/safidy/.local/lib/python3.9/site-packages/airflow/operators/python.py", line 252, in execute_callable
    return self.python_callable(*self.op_args, **self.op_kwargs)
  File "/home/safidy/airflow/dags/air_pollution_data_dag.py", line 15, in fetch_air_pollution_data
    response = requests.get(url)
NameError: name 'requests' is not defined
[2024-08-05T11:38:15.598+0300] {taskinstance.py:1206} INFO - Marking task as UP_FOR_RETRY. dag_id=air_pollution_analysis, task_id=fetch_air_pollution_data, run_id=manual__2024-08-05T08:38:08.208342+00:00, execution_date=20240805T083808, start_date=20240805T083815, end_date=20240805T083815
[2024-08-05T11:38:15.610+0300] {standard_task_runner.py:110} ERROR - Failed to execute job 236 for task fetch_air_pollution_data (name 'requests' is not defined; 48583)
[2024-08-05T11:38:15.624+0300] {local_task_job_runner.py:243} INFO - Task exited with return code 1
[2024-08-05T11:38:15.652+0300] {taskinstance.py:3503} INFO - 0 downstream tasks scheduled from follow-on schedule check
[2024-08-05T11:38:15.653+0300] {local_task_job_runner.py:222} INFO - ::endgroup::
