[2024-08-05T11:52:51.613+0300] {local_task_job_runner.py:120} INFO - ::group::Pre task execution logs
[2024-08-05T11:52:51.721+0300] {taskinstance.py:2076} INFO - Dependencies all met for dep_context=non-requeueable deps ti=<TaskInstance: process_air_pollution_data_dag.clean_data manual__2024-08-05T08:52:42.482976+00:00 [queued]>
[2024-08-05T11:52:51.734+0300] {taskinstance.py:2076} INFO - Dependencies all met for dep_context=requeueable deps ti=<TaskInstance: process_air_pollution_data_dag.clean_data manual__2024-08-05T08:52:42.482976+00:00 [queued]>
[2024-08-05T11:52:51.735+0300] {taskinstance.py:2306} INFO - Starting attempt 1 of 2
[2024-08-05T11:52:51.758+0300] {taskinstance.py:2330} INFO - Executing <Task(PythonOperator): clean_data> on 2024-08-05 08:52:42.482976+00:00
[2024-08-05T11:52:51.766+0300] {standard_task_runner.py:64} INFO - Started process 51298 to run task
[2024-08-05T11:52:51.773+0300] {standard_task_runner.py:90} INFO - Running: ['airflow', 'tasks', 'run', 'process_air_pollution_data_dag', 'clean_data', 'manual__2024-08-05T08:52:42.482976+00:00', '--job-id', '241', '--raw', '--subdir', 'DAGS_FOLDER/process_air_pollution_data_dag.py', '--cfg-path', '/tmp/tmp0mxuwus7']
[2024-08-05T11:52:51.774+0300] {standard_task_runner.py:91} INFO - Job 241: Subtask clean_data
[2024-08-05T11:52:51.853+0300] {task_command.py:426} INFO - Running <TaskInstance: process_air_pollution_data_dag.clean_data manual__2024-08-05T08:52:42.482976+00:00 [running]> on host std21092
[2024-08-05T11:52:51.973+0300] {taskinstance.py:2648} INFO - Exporting env vars: AIRFLOW_CTX_DAG_OWNER='airflow' AIRFLOW_CTX_DAG_ID='process_air_pollution_data_dag' AIRFLOW_CTX_TASK_ID='clean_data' AIRFLOW_CTX_EXECUTION_DATE='2024-08-05T08:52:42.482976+00:00' AIRFLOW_CTX_TRY_NUMBER='1' AIRFLOW_CTX_DAG_RUN_ID='manual__2024-08-05T08:52:42.482976+00:00'
[2024-08-05T11:52:51.982+0300] {taskinstance.py:430} INFO - ::endgroup::
[2024-08-05T11:52:52.047+0300] {taskinstance.py:441} INFO - ::group::Post task execution logs
[2024-08-05T11:52:52.048+0300] {taskinstance.py:2905} ERROR - Task failed with exception
Traceback (most recent call last):
  File "/home/safidy/.local/lib/python3.9/site-packages/pandas/core/indexes/base.py", line 3653, in get_loc
    return self._engine.get_loc(casted_key)
  File "pandas/_libs/index.pyx", line 147, in pandas._libs.index.IndexEngine.get_loc
  File "pandas/_libs/index.pyx", line 176, in pandas._libs.index.IndexEngine.get_loc
  File "pandas/_libs/hashtable_class_helper.pxi", line 7080, in pandas._libs.hashtable.PyObjectHashTable.get_item
  File "pandas/_libs/hashtable_class_helper.pxi", line 7088, in pandas._libs.hashtable.PyObjectHashTable.get_item
KeyError: 'timestamp'

The above exception was the direct cause of the following exception:

Traceback (most recent call last):
  File "/home/safidy/.local/lib/python3.9/site-packages/airflow/models/taskinstance.py", line 465, in _execute_task
    result = _execute_callable(context=context, **execute_callable_kwargs)
  File "/home/safidy/.local/lib/python3.9/site-packages/airflow/models/taskinstance.py", line 432, in _execute_callable
    return execute_callable(context=context, **execute_callable_kwargs)
  File "/home/safidy/.local/lib/python3.9/site-packages/airflow/models/baseoperator.py", line 401, in wrapper
    return func(self, *args, **kwargs)
  File "/home/safidy/.local/lib/python3.9/site-packages/airflow/operators/python.py", line 235, in execute
    return_value = self.execute_callable()
  File "/home/safidy/.local/lib/python3.9/site-packages/airflow/operators/python.py", line 252, in execute_callable
    return self.python_callable(*self.op_args, **self.op_kwargs)
  File "/home/safidy/airflow/dags/process_air_pollution_data_dag.py", line 10, in clean_data
    df['timestamp'] = pd.to_datetime(df['timestamp'], unit='s')
  File "/home/safidy/.local/lib/python3.9/site-packages/pandas/core/frame.py", line 3761, in __getitem__
    indexer = self.columns.get_loc(key)
  File "/home/safidy/.local/lib/python3.9/site-packages/pandas/core/indexes/base.py", line 3655, in get_loc
    raise KeyError(key) from err
KeyError: 'timestamp'
[2024-08-05T11:52:52.065+0300] {taskinstance.py:1206} INFO - Marking task as UP_FOR_RETRY. dag_id=process_air_pollution_data_dag, task_id=clean_data, run_id=manual__2024-08-05T08:52:42.482976+00:00, execution_date=20240805T085242, start_date=20240805T085251, end_date=20240805T085252
[2024-08-05T11:52:52.082+0300] {standard_task_runner.py:110} ERROR - Failed to execute job 241 for task clean_data ('timestamp'; 51298)
[2024-08-05T11:52:52.109+0300] {local_task_job_runner.py:243} INFO - Task exited with return code 1
[2024-08-05T11:52:52.144+0300] {taskinstance.py:3503} INFO - 0 downstream tasks scheduled from follow-on schedule check
[2024-08-05T11:52:52.145+0300] {local_task_job_runner.py:222} INFO - ::endgroup::
