[2024-08-05T10:06:09.265+0300] {local_task_job_runner.py:120} INFO - ::group::Pre task execution logs
[2024-08-05T10:06:09.291+0300] {taskinstance.py:2076} INFO - Dependencies all met for dep_context=non-requeueable deps ti=<TaskInstance: air_pollution_analysis.merge_data manual__2024-08-05T07:00:39.002991+00:00 [queued]>
[2024-08-05T10:06:09.298+0300] {taskinstance.py:2076} INFO - Dependencies all met for dep_context=requeueable deps ti=<TaskInstance: air_pollution_analysis.merge_data manual__2024-08-05T07:00:39.002991+00:00 [queued]>
[2024-08-05T10:06:09.298+0300] {taskinstance.py:2306} INFO - Starting attempt 2 of 2
[2024-08-05T10:06:09.316+0300] {taskinstance.py:2330} INFO - Executing <Task(PythonOperator): merge_data> on 2024-08-05 07:00:39.002991+00:00
[2024-08-05T10:06:09.322+0300] {standard_task_runner.py:64} INFO - Started process 32223 to run task
[2024-08-05T10:06:09.327+0300] {standard_task_runner.py:90} INFO - Running: ['airflow', 'tasks', 'run', 'air_pollution_analysis', 'merge_data', 'manual__2024-08-05T07:00:39.002991+00:00', '--job-id', '214', '--raw', '--subdir', 'DAGS_FOLDER/air_pollution_analysis_dag.py', '--cfg-path', '/tmp/tmpqid67at1']
[2024-08-05T10:06:09.327+0300] {standard_task_runner.py:91} INFO - Job 214: Subtask merge_data
[2024-08-05T10:06:09.372+0300] {task_command.py:426} INFO - Running <TaskInstance: air_pollution_analysis.merge_data manual__2024-08-05T07:00:39.002991+00:00 [running]> on host std21092
[2024-08-05T10:06:09.449+0300] {taskinstance.py:2648} INFO - Exporting env vars: AIRFLOW_CTX_DAG_OWNER='airflow' AIRFLOW_CTX_DAG_ID='air_pollution_analysis' AIRFLOW_CTX_TASK_ID='merge_data' AIRFLOW_CTX_EXECUTION_DATE='2024-08-05T07:00:39.002991+00:00' AIRFLOW_CTX_TRY_NUMBER='2' AIRFLOW_CTX_DAG_RUN_ID='manual__2024-08-05T07:00:39.002991+00:00'
[2024-08-05T10:06:09.450+0300] {taskinstance.py:430} INFO - ::endgroup::
[2024-08-05T10:06:09.451+0300] {logging_mixin.py:188} INFO - Erreur lors de la fusion des donn√©es : [Errno 2] No such file or directory: '/path/to/your/data/cleaned_data.csv'
[2024-08-05T10:06:09.452+0300] {taskinstance.py:441} INFO - ::group::Post task execution logs
[2024-08-05T10:06:09.452+0300] {taskinstance.py:2905} ERROR - Task failed with exception
Traceback (most recent call last):
  File "/home/safidy/.local/lib/python3.9/site-packages/airflow/models/taskinstance.py", line 465, in _execute_task
    result = _execute_callable(context=context, **execute_callable_kwargs)
  File "/home/safidy/.local/lib/python3.9/site-packages/airflow/models/taskinstance.py", line 432, in _execute_callable
    return execute_callable(context=context, **execute_callable_kwargs)
  File "/home/safidy/.local/lib/python3.9/site-packages/airflow/models/baseoperator.py", line 401, in wrapper
    return func(self, *args, **kwargs)
  File "/home/safidy/.local/lib/python3.9/site-packages/airflow/operators/python.py", line 235, in execute
    return_value = self.execute_callable()
  File "/home/safidy/.local/lib/python3.9/site-packages/airflow/operators/python.py", line 252, in execute_callable
    return self.python_callable(*self.op_args, **self.op_kwargs)
  File "/home/safidy/airflow/dags/air_pollution_analysis_dag.py", line 64, in merge_data
    merged_df = pd.merge(air_pollution_df, demographic_df, left_on='city', right_on='Location')
UnboundLocalError: local variable 'air_pollution_df' referenced before assignment
[2024-08-05T10:06:09.456+0300] {taskinstance.py:1206} INFO - Marking task as FAILED. dag_id=air_pollution_analysis, task_id=merge_data, run_id=manual__2024-08-05T07:00:39.002991+00:00, execution_date=20240805T070039, start_date=20240805T070609, end_date=20240805T070609
[2024-08-05T10:06:09.466+0300] {standard_task_runner.py:110} ERROR - Failed to execute job 214 for task merge_data (local variable 'air_pollution_df' referenced before assignment; 32223)
[2024-08-05T10:06:09.498+0300] {local_task_job_runner.py:243} INFO - Task exited with return code 1
[2024-08-05T10:06:09.522+0300] {taskinstance.py:3503} INFO - 0 downstream tasks scheduled from follow-on schedule check
[2024-08-05T10:06:09.528+0300] {local_task_job_runner.py:222} INFO - ::endgroup::
